<robot name="RPR">    

    <link name = "base_link">
        <visual>
            <geometry>
                <cylinder length="0.15" radius="0.025" />
            </geometry> 
            <material name = "base">
                <color rgba="0 1 0 1" />
            </material>
            <origin xyz="0 0 0.075" />
        </visual>
        <visual>
            <origin xyz="0 0 0.15" rpy="1.57 0 1.57" />
            <geometry>
                <cylinder length="0.06" radius="0.03" />
            </geometry>
            <material name="rot">
                <color rgba="1 0 0 1" />
            </material>
        </visual>
        <inertial>
            <origin xyz="0 0 0" rpy="0 0 0" /> <!-- center of mass -->
            <mass value="0.1" />
            <inertia ixx="0" ixy="0" ixz="0" iyy="0" iyz="0" izz="0"/>
        </inertial>
    </link>

    <link name = "Link2">
        <visual>
            <origin xyz="0 0.2 0" rpy= "1.57 0 0" />
            <geometry>
                <cylinder length="0.4" radius="0.02"/>
            </geometry> 
            <material name = "rot">
                <color rgba="1 0 0 1" />
            </material>
        </visual>
        <visual>
            <origin xyz="0 0.4 0" rpy="0 0 0" />
            <geometry>
                <box size="0.06 0.06 0.09" />
            </geometry>
            <material name="prism">
                <color rgba="0 0 1 1" />
            </material>
        </visual>
        <inertial>
            <origin xyz="0 0 0" rpy="0 0 0" /> <!-- center of mass -->
            <mass value="0.2" />
            <inertia ixx="0" ixy="0" ixz="0" iyy="0" iyz="0" izz="0"/>
        </inertial>
    </link>

    <link name = "Link3">
        <visual>
            <origin xyz="0 0 0.15" rpy="0 0 0" />
            <geometry>
                <box size="0.03 0.03 0.3" />
            </geometry> 
            <material name = "prism">
                <color rgba="0 0 1 1" />
            </material>
        </visual>
        <visual>
            <origin xyz="0 0 0.3" rpy="0 1.57 0" />
            <geometry>
                <cylinder length="0.06" radius="0.03" />
            </geometry>
            <material name="rot">
                <color rgba="1 0 0 1" />
            </material>
        </visual>
        <inertial>
            <origin xyz="0 0 0" rpy="0 0 0" />
            <mass value="0.3" />
            <inertia ixx="0" ixy="0" ixz="0" iyy="0" iyz="0" izz="0"/>
        </inertial>
    </link>

    <link name = "Link4">
        <visual>
            <origin xyz="0.1 0 0" rpy="0 1.57 0" />
            <geometry>
                <cylinder length="0.16" radius="0.02" />
            </geometry> 
            <material name = "rot">
                <color rgba="0 0 1 0" />
            </material>
        </visual>
        <inertial>
            <origin xyz="0 0 0" rpy="0 0 0" />
            <mass value="0.4" />
            <inertia ixx="0" ixy="0" ixz="0" iyy="0" iyz="0" izz="0"/>
        </inertial>
    </link>

    <link name="ee" />

    <joint name = "Joint1" type="revolute">
        <parent link = "base_link" />
        <child link = "Link2" />
        <origin xyz = "0 0 0.15" rpy="0 1.57 0"/>
        <axis xyz = "0 0 1" />
        <limit lower = "-3.14" upper = "3.14" effort = "0" velocity = "1" /> 
        <dynamics damping="0.0" friction="0.0"/>
    </joint>


    <joint name = "Joint2" type="prismatic">
        <parent link = "Link2" />
        <child link = "Link3" />
        <origin xyz = "0 0.4 0" rpy="0 -1.57 0"/>
        <axis xyz = "0 0 1" />
        <limit lower = "-0.3" upper = "+0" effort = "0" velocity = "1"/>
        <dynamics damping="0.0" friction="0.0"/>
    </joint>


    <joint name = "Joint3" type="revolute">
        <parent link = "Link3" />
        <child link = "Link4" />
        <origin xyz = "0 0 0.3" rpy = "0 0 1.57"/>
        <axis xyz = "0 0 1" />
        <limit lower = "-3.14" upper = "3.14" effort = "0" velocity = "1" />
        <dynamics damping="0.0" friction="0.0"/>
    </joint>

    <joint name="ee_link" type="fixed">
    	<parent link="Link4" />
    	<child link="ee" />
        <origin xyz="0.16 0 0" rpy="0 1.57 0" />
    </joint>
</robot>
